<?xml version="1.0" ?>
<!-- =================================================================================== -->
<!-- |    This document was autogenerated by xacro from robot_core.xacro               | -->
<!-- |    EDITING THIS FILE BY HAND IS NOT RECOMMENDED                                 | -->
<!-- =================================================================================== -->
<!-- This URDF was automatically created by SolidWorks to URDF Exporter! Originally created by Stephen Brawner (brawner@gmail.com) 
     Commit Version: 1.6.0-4-g7f85cfe  Build Version: 1.6.7995.38578
     For more information, please see http://wiki.ros.org/sw_urdf_exporter -->
<robot name="hendbot">
  <material name="white">
    <color rgba="1 1 1 1"/>
  </material>
  <material name="orange">
    <color rgba="1 0.3 0.1 1"/>
  </material>
  <material name="blue">
    <color rgba="0.2 0.2 1 1"/>
  </material>
  <material name="black">
    <color rgba="0 0 0 1"/>
  </material>
  <link name="base_link">

  </link>
  <!-- BASE_FOOTPRINT LINK -->
  <joint name="base_footprint_joint" type="fixed">
    <parent link="base_link"/>
    <child link="base_footprint"/>
    <origin rpy="0 0 0" xyz="0 0 0"/>
  </joint>
  <link name="base_footprint">
  </link>
  <link name="hend_link">
    <inertial>
      <origin rpy="0 0 0" xyz="0.328696423253543 -2.60874698367187E-17 0.0950289066631501"/>
      <mass value="43.4880454963273"/>
      <inertia ixx="0.580105726031867" ixy="4.51081599921307E-16" ixz="-0.0125188942101638" iyy="1.698173281021" iyz="1.45266351536115E-16" izz="2.0236419336975"/>
    </inertial>
    <visual>
      <origin rpy="0 0 0" xyz="0 0 0"/>
      <geometry>
        <mesh filename="package://hendbot/meshes/base_link.STL"/>
      </geometry>
      <material name="">
        <color rgba="0.792156862745098 0.819607843137255 0.933333333333333 1"/>
      </material>
    </visual>
    <collision>
      <origin rpy="0 0 0" xyz="0 0 0"/>
      <geometry>
        <mesh filename="package://hendbot/meshes/base_link.STL"/>
      </geometry>
    </collision>
  </link>
  <joint name="hend_joint" type="fixed">
    <parent link="base_link"/>
    <child link="hend_link"/>
    <origin xyz="-0.33246 0 0"/>
  </joint>
  <gazebo reference="hend_link">
    <material>Gazebo/Black</material>
  </gazebo>
  <link name="RBW_Link">
    <inertial>
      <origin rpy="0 0 0" xyz="-5.55111512312578E-17 -6.93889390390723E-18 -0.0300000000000001"/>
      <mass value="2.83020427295128"/>
      <inertia ixx="0.00487431930909034" ixy="2.16840434497101E-19" ixz="-2.6439984961889E-21" iyy="0.00487431930909034" iyz="7.20071906052003E-21" izz="0.00805051605440992"/>
    </inertial>
    <visual>
      <origin rpy="0 0 0" xyz="0 0 0"/>
      <geometry>
        <mesh filename="package://hendbot/meshes/RBW_Link.STL"/>
      </geometry>
      <material name="">
        <color rgba="0.101960784313725 0.101960784313725 0.101960784313725 1"/>
      </material>
    </visual>
    <collision>
      <origin rpy="0 0 0" xyz="0 0 0"/>
      <geometry>
        <mesh filename="package://hendbot/meshes/RBW_Link.STL"/>
      </geometry>
    </collision>
  </link>
  <joint name="RBW_Joint" type="fixed">
    <origin rpy="-1.5708 0.11175 0" xyz="0.05 -0.215 0.035"/>
    <parent link="hend_link"/>
    <child link="RBW_Link"/>
    <axis xyz="0 0 1"/>
    <limit effort="100" velocity="100"/>
    <dynamics damping="0.1" friction="0.1"/>
  </joint>
  <gazebo reference="RBW_Link">
    <material>Gazebo/Orange</material>
    <mu1 value="0.1"/>
    <mu2 value="0.1"/>
  </gazebo>
  <link name="LBW_Link">
    <inertial>
      <origin rpy="0 0 0" xyz="-5.55111512312578E-17 1.66533453693773E-16 0.03"/>
      <mass value="2.83020427295128"/>
      <inertia ixx="0.00487431930909034" ixy="-5.42101086242752E-19" ixz="-7.92471037265887E-20" iyy="0.00487431930909034" iyz="2.11365740243217E-19" izz="0.00805051605440992"/>
    </inertial>
    <visual>
      <origin rpy="0 0 0" xyz="0 0 0"/>
      <geometry>
        <mesh filename="package://hendbot/meshes/LBW_Link.STL"/>
      </geometry>
      <material name="">
        <color rgba="0.101960784313725 0.101960784313725 0.101960784313725 1"/>
      </material>
    </visual>
    <collision>
      <origin rpy="0 0 0" xyz="0 0 0"/>
      <geometry>
        <mesh filename="package://hendbot/meshes/LBW_Link.STL"/>
      </geometry>
    </collision>
  </link>
  <joint name="LBW_Joint" type="fixed">
    <origin rpy="1.5708 -1.1717 3.1416" xyz="0.05 0.215 0.035"/>
    <parent link="hend_link"/>
    <child link="LBW_Link"/>
    <axis xyz="0 0 1"/>
    <limit effort="100" velocity="100"/>
    <dynamics damping="0.1" friction="0.1"/>
  </joint>
  <gazebo reference="LBW_Link">
    <material>Gazebo/Orange</material>
    <mu1 value="0.1"/>
    <mu2 value="0.1"/>
  </gazebo>
  <link name="WRBelt_Link">
    <inertial>
      <origin rpy="0 0 0" xyz="-5.06990479587008E-06 3.91305833367592E-06 -0.03"/>
      <mass value="2.83020427295128"/>
      <inertia ixx="0.00487431930909035" ixy="2.16840434497101E-19" ixz="9.79617266491298E-36" iyy="0.00487431930909035" iyz="7.94183936865276E-36" izz="0.00805051605440992"/>
    </inertial>
    <visual>
      <origin rpy="0 0 0" xyz="0 0 0"/>
      <geometry>
        <mesh filename="package://hendbot/meshes/WRBelt_Link.STL"/>
      </geometry>
      <material name="">
        <color rgba="0.101960784313725 0.101960784313725 0.101960784313725 1"/>
      </material>
    </visual>
    <collision>
      <origin rpy="0 0 0" xyz="0 0 0"/>
      <geometry>
        <mesh filename="package://hendbot/meshes/WRBelt_Link.STL"/>
      </geometry>
    </collision>
  </link>
  <joint name="WRBelt_Joint" type="continuous">
    <origin rpy="-1.5708 0.65732 0" xyz="0.00004 -0.215 0.035052"/>
    <parent link="base_link"/>
    <child link="WRBelt_Link"/>
    <axis xyz="0 0 1"/>
    <limit effort="100" velocity="100"/>
    <dynamics damping="0.1" friction="0.1"/>
  </joint>
  <gazebo reference="WRBelt_Link">
    <material>Gazebo/Blue</material>
  </gazebo>
  <link name="WLBelt_Link">
    <inertial>
      <origin rpy="0 0 0" xyz="6.00761815290098E-06 2.21911790831281E-06 0.03"/>
      <mass value="2.83020427295128"/>
      <inertia ixx="0.00487431930909034" ixy="1.0842021724855E-19" ixz="-5.9576058536142E-21" iyy="0.00487431930909034" iyz="-3.72125275370687E-22" izz="0.00805051605440991"/>
    </inertial>
    <visual>
      <origin rpy="0 0 0" xyz="0 0 0"/>
      <geometry>
        <mesh filename="package://hendbot/meshes/WLBelt_Link.STL"/>
      </geometry>
      <material name="">
        <color rgba="0.101960784313725 0.101960784313725 0.101960784313725 1"/>
      </material>
    </visual>
    <collision>
      <origin rpy="0 0 0" xyz="0 0 0"/>
      <geometry>
        <mesh filename="package://hendbot/meshes/WLBelt_Link.STL"/>
      </geometry>
    </collision>
  </link>
  <joint name="WLBelt_Joint" type="continuous">
    <origin rpy="1.5708 0.35384 -3.1416" xyz="0.00004 0.215 0.035052"/>
    <parent link="base_link"/>
    <child link="WLBelt_Link"/>
    <axis xyz="0 0 1"/>
    <limit effort="100" velocity="100"/>
    <dynamics damping="0.1" friction="0.1"/>
  </joint>
  <gazebo reference="WLBelt_Link">
    <material>Gazebo/Blue</material>
  </gazebo>
  <link name="RFW_Link">
    <inertial>
      <origin rpy="0 0 0" xyz="1.11022302462516E-16 5.55111512312578E-17 -0.0299999999999999"/>
      <mass value="2.83020427295128"/>
      <inertia ixx="0.00487431930909035" ixy="5.42101086242752E-19" ixz="-1.31497251854061E-19" iyy="0.00487431930909034" iyz="-2.24427537663732E-19" izz="0.00805051605440992"/>
    </inertial>
    <visual>
      <origin rpy="0 0 0" xyz="0 0 0"/>
      <geometry>
        <mesh filename="package://hendbot/meshes/RFW_Link.STL"/>
      </geometry>
      <material name="">
        <color rgba="0.101960784313725 0.101960784313725 0.101960784313725 1"/>
      </material>
    </visual>
    <collision>
      <origin rpy="0 0 0" xyz="0 0 0"/>
      <geometry>
        <mesh filename="package://hendbot/meshes/RFW_Link.STL"/>
      </geometry>
    </collision>
  </link>
  <joint name="RFW_joint" type="fixed">
    <origin rpy="1.5708 0.34292 -3.1416" xyz="0.61491 -0.215 0.035103"/>
    <parent link="hend_link"/>
    <child link="RFW_Link"/>
    <axis xyz="0 0 1"/>
    <limit effort="100" velocity="100"/>
    <dynamics damping="0.1" friction="0.1"/>
  </joint>
  <gazebo reference="RFW_Link">
    <material>Gazebo/Orange</material>
    <mu1 value="0.1"/>
    <mu2 value="0.1"/>
  </gazebo>
  <link name="LFW_Link">
    <inertial>
      <origin rpy="0 0 0" xyz="8.32667268468867E-17 5.55111512312578E-17 0.0299999999999999"/>
      <mass value="2.83020427295128"/>
      <inertia ixx="0.00487431930909034" ixy="0" ixz="-1.10167760345487E-18" iyy="0.00487431930909034" iyz="-2.59138014296351E-20" izz="0.00805051605440992"/>
    </inertial>
    <visual>
      <origin rpy="0 0 0" xyz="0 0 0"/>
      <geometry>
        <mesh filename="package://hendbot/meshes/LFW_Link.STL"/>
      </geometry>
      <material name="">
        <color rgba="0.101960784313725 0.101960784313725 0.101960784313725 1"/>
      </material>
    </visual>
    <collision>
      <origin rpy="0 0 0" xyz="0 0 0"/>
      <geometry>
        <mesh filename="package://hendbot/meshes/LFW_Link.STL"/>
      </geometry>
    </collision>
  </link>
  <joint name="LFW_Joint" type="fixed">
    <origin rpy="1.5708 0.76776 -3.1416" xyz="0.61491 0.215 0.035103"/>
    <parent link="hend_link"/>
    <child link="LFW_Link"/>
    <axis xyz="0 0 1"/>
    <limit effort="100" velocity="100"/>
    <dynamics damping="0.1" friction="0.1"/>
  </joint>
  <gazebo reference="LFW_Link">
    <material>Gazebo/Orange</material>
    <mu1 value="0.1"/>
    <mu2 value="0.1"/>
  </gazebo>
  <link name="RFFW_Link">
    <inertial>
      <origin rpy="0 0 0" xyz="2.77555756156289E-17 -2.77555756156289E-17 -0.0300000000000004"/>
      <mass value="2.83020427295128"/>
      <inertia ixx="0.00487431930909035" ixy="0" ixz="-3.02041096973436E-18" iyy="0.00487431930909034" iyz="5.63440194482331E-18" izz="0.00805051605440992"/>
    </inertial>
    <visual>
      <origin rpy="0 0 0" xyz="0 0 0"/>
      <geometry>
        <mesh filename="package://hendbot/meshes/RFFW_Link.STL"/>
      </geometry>
      <material name="">
        <color rgba="0.101960784313725 0.101960784313725 0.101960784313725 1"/>
      </material>
    </visual>
    <collision>
      <origin rpy="0 0 0" xyz="0 0 0"/>
      <geometry>
        <mesh filename="package://hendbot/meshes/RFFW_Link.STL"/>
      </geometry>
    </collision>
  </link>
  <joint name="RFFW_Joint" type="continuous">
    <origin rpy="-1.5708 -0.76747 0" xyz="0.61491 -0.31 0.035103"/>
    <parent link="hend_link"/>
    <child link="RFFW_Link"/>
    <axis xyz="0 0 1"/>
    <limit effort="100" lower="0" upper="0.785" velocity="100"/>
    <dynamics damping="0.1" friction="0.1"/>
  </joint>
  <gazebo reference="RFFW_Link">
    <material>Gazebo/Orange</material>
    <mu1 value="0.1"/>
    <mu2 value="0.1"/>
  </gazebo>
  <link name="RF_Link">
    <inertial>
      <origin rpy="0 0 0" xyz="0.116802763167045 -0.00888303440495468 -0.0451647957579333"/>
      <mass value="0.204447676178174"/>
      <inertia ixx="0.000307626591941256" ixy="6.45911023981527E-06" ixz="-0.000427165594157326" iyy="0.00234079047956499" iyz="1.81632274337046E-06" izz="0.0023527687683258"/>
    </inertial>
    <visual>
      <origin rpy="0 0 0" xyz="0 0 0"/>
      <geometry>
        <mesh filename="package://hendbot/meshes/RF_Link.STL"/>
      </geometry>
      <material name="">
        <color rgba="0.792156862745098 0.819607843137255 0.933333333333333 1"/>
      </material>
    </visual>
    <collision>
      <origin rpy="0 0 0" xyz="0 0 0"/>
      <geometry>
        <mesh filename="package://hendbot/meshes/RF_Link.STL"/>
      </geometry>
    </collision>
  </link>
  <joint name="RF_Joint" type="fixed">
    <origin rpy="0 0 0.504452455101276" xyz="0 0.01 0"/>
    <parent link="RFFW_Link"/>
    <child link="RF_Link"/>
    <axis xyz="0 0 0"/>
    <limit effort="0" lower="0" upper="0" velocity="0"/>
  </joint>
  <link name="RW_Link">
    <inertial>
      <origin rpy="0 0 0" xyz="8.32667268468867E-17 5.55111512312578E-16 -0.03"/>
      <mass value="0.466526509058084"/>
      <inertia ixx="0.000434452811560341" ixy="-4.1972501374133E-21" ixz="-1.25523865608312E-20" iyy="0.000434452811560341" iyz="2.74929016542641E-21" izz="0.000588989717685832"/>
    </inertial>
    <visual>
      <origin rpy="0 0 0" xyz="0 0 0"/>
      <geometry>
        <mesh filename="package://hendbot/meshes/RW_Link.STL"/>
      </geometry>
      <material name="">
        <color rgba="0 0 0.0470588235294118 1"/>
      </material>
    </visual>
    <collision>
      <origin rpy="0 0 0" xyz="0 0 0"/>
      <geometry>
        <mesh filename="package://hendbot/meshes/RW_Link.STL"/>
      </geometry>
    </collision>
  </link>
  <joint name="RW_Joint" type="fixed">
    <origin rpy="0 0 -1.3078" xyz="0.29495 -0.010546 0"/>
    <parent link="RF_Link"/>
    <child link="RW_Link"/>
    <axis xyz="0 0 1"/>
    <limit effort="100" lower="0" upper="0" velocity="100"/>
    <dynamics damping="0.1" friction="0.1"/>
  </joint>
  <gazebo reference="RW_Link">
    <material>Gazebo/Orange</material>
    <mu1 value="0.1"/>
    <mu2 value="0.1"/>
  </gazebo>
  <link name="LFFW_Link">
    <inertial>
      <origin rpy="0 0 0" xyz="0 0 0.0300000000000001"/>
      <mass value="2.83020427295128"/>
      <inertia ixx="0.00487431930909034" ixy="4.33680868994202E-19" ixz="4.16665986175241E-19" iyy="0.00487431930909035" iyz="-2.13864119876703E-19" izz="0.00805051605440992"/>
    </inertial>
    <visual>
      <origin rpy="0 0 0" xyz="0 0 0"/>
      <geometry>
        <mesh filename="package://hendbot/meshes/LFFW_Link.STL"/>
      </geometry>
      <material name="">
        <color rgba="0.101960784313725 0.101960784313725 0.101960784313725 1"/>
      </material>
    </visual>
    <collision>
      <origin rpy="0 0 0" xyz="0 0 0"/>
      <geometry>
        <mesh filename="package://hendbot/meshes/LFFW_Link.STL"/>
      </geometry>
    </collision>
  </link>
  <joint name="LFFW_Joint" type="continuous">
    <origin rpy="1.5708 -1.005 3.1416" xyz="0.61491 0.30998 0.035103"/>
    <parent link="hend_link"/>
    <child link="LFFW_Link"/>
    <axis xyz="0 0 1"/>
    <limit effort="100" lower="0" upper="0.785" velocity="100"/>
    <dynamics damping="0.1" friction="0.1"/>
  </joint>
  <gazebo reference="LFFW_Link">
    <material>Gazebo/Orange</material>
    <mu1 value="0.1"/>
    <mu2 value="0.1"/>
  </gazebo>
  <link name="LF_Link">
    <inertial>
      <origin rpy="0 0 0" xyz="0.121636063593485 0.00012866330010497 0.0451847908566546"/>
      <mass value="0.204447835856117"/>
      <inertia ixx="0.000307626696889609" ixy="-6.45895372599709E-06" ixz="0.000427165888889448" iyy="0.00234079146265305" iyz="1.81619833910581E-06" izz="0.00235276956824831"/>
    </inertial>
    <visual>
      <origin rpy="0 0 0" xyz="0 0 0"/>
      <geometry>
        <mesh filename="package://hendbot/meshes/LF_Link.STL"/>
      </geometry>
      <material name="">
        <color rgba="0.792156862745098 0.819607843137255 0.933333333333333 1"/>
      </material>
    </visual>
    <collision>
      <origin rpy="0 0 0" xyz="0 0 0"/>
      <geometry>
        <mesh filename="package://hendbot/meshes/LF_Link.STL"/>
      </geometry>
    </collision>
  </link>
  <joint name="LF_Joint" type="fixed">
    <origin rpy="0 0 1.91705217764631" xyz="0 0 0"/>
    <parent link="LFFW_Link"/>
    <child link="LF_Link"/>
    <axis xyz="0 0 0"/>
  </joint>
  <link name="LW_Link">
    <inertial>
      <origin rpy="0 0 0" xyz="4.02455846426619E-16 1.11022302462516E-15 0.03"/>
      <mass value="0.466526509058084"/>
      <inertia ixx="0.000434452811560341" ixy="-5.43525904847875E-20" ixz="1.68763772702419E-20" iyy="0.000434452811560341" iyz="7.59802921517958E-21" izz="0.000588989717685832"/>
    </inertial>
    <visual>
      <origin rpy="0 0 0" xyz="0 0 0"/>
      <geometry>
        <mesh filename="package://hendbot/meshes/LW_Link.STL"/>
      </geometry>
      <material name="">
        <color rgba="0 0 0.0470588235294118 1"/>
      </material>
    </visual>
    <collision>
      <origin rpy="0 0 0" xyz="0 0 0"/>
      <geometry>
        <mesh filename="package://hendbot/meshes/LW_Link.STL"/>
      </geometry>
    </collision>
  </link>
  <joint name="LW_Joint" type="fixed">
    <origin rpy="0 0 1.79029753611258" xyz="0.299785014663327 0.00179117333342351 0"/>
    <parent link="LF_Link"/>
    <child link="LW_Link"/>
    <axis xyz="0 0 -1"/>
    <limit effort="100" lower="0" upper="0.785" velocity="100"/>
    <dynamics damping="0.1" friction="0.1"/>
  </joint>
  <gazebo reference="LW_Link">
    <material>Gazebo/Orange</material>
    <mu1 value="0.1"/>
    <mu2 value="0.1"/>
  </gazebo>
</robot>
