<sdf version='1.7'>
  <world name='default'>
    <light name='sun' type='directional'>
      <cast_shadows>1</cast_shadows>
      <pose>0 0 10 0 -0 0</pose>
      <diffuse>0.8 0.8 0.8 1</diffuse>
      <specular>0.2 0.2 0.2 1</specular>
      <attenuation>
        <range>1000</range>
        <constant>0.9</constant>
        <linear>0.01</linear>
        <quadratic>0.001</quadratic>
      </attenuation>
      <direction>-0.5 0.1 -0.9</direction>
      <spot>
        <inner_angle>0</inner_angle>
        <outer_angle>0</outer_angle>
        <falloff>0</falloff>
      </spot>
    </light>
    <model name='ground_plane'>
      <static>1</static>
      <link name='link'>
        <collision name='collision'>
          <geometry>
            <plane>
              <normal>0 0 1</normal>
              <size>100 100</size>
            </plane>
          </geometry>
          <surface>
            <friction>
              <ode>
                <mu>100</mu>
                <mu2>50</mu2>
              </ode>
              <torsional>
                <ode/>
              </torsional>
            </friction>
            <contact>
              <ode/>
            </contact>
            <bounce/>
          </surface>
          <max_contacts>10</max_contacts>
        </collision>
        <visual name='visual'>
          <cast_shadows>0</cast_shadows>
          <geometry>
            <plane>
              <normal>0 0 1</normal>
              <size>100 100</size>
            </plane>
          </geometry>
          <material>
            <script>
              <uri>file://media/materials/scripts/gazebo.material</uri>
              <name>Gazebo/Grey</name>
            </script>
          </material>
        </visual>
        <self_collide>0</self_collide>
        <enable_wind>0</enable_wind>
        <kinematic>0</kinematic>
      </link>
    </model>
    <gravity>0 0 -9.8</gravity>
    <magnetic_field>6e-06 2.3e-05 -4.2e-05</magnetic_field>
    <atmosphere type='adiabatic'/>
    <physics type='ode'>
      <max_step_size>0.001</max_step_size>
      <real_time_factor>1</real_time_factor>
      <real_time_update_rate>1000</real_time_update_rate>
    </physics>
    <scene>
      <ambient>0.4 0.4 0.4 1</ambient>
      <background>0.7 0.7 0.7 1</background>
      <shadows>1</shadows>
    </scene>
    <wind/>
    <spherical_coordinates>
      <surface_model>EARTH_WGS84</surface_model>
      <latitude_deg>0</latitude_deg>
      <longitude_deg>0</longitude_deg>
      <elevation>0</elevation>
      <heading_deg>0</heading_deg>
    </spherical_coordinates>
    <model name='hendbot'>
      <link name='base_link'>
        <inertial>
          <pose>-0.003005 -0 0.083073 0 -0 0</pose>
          <mass>54.9089</mass>
          <inertia>
            <ixx>1.31716</ixx>
            <ixy>-1.29347e-07</ixy>
            <ixz>-0.0104342</ixz>
            <iyy>2.67172</iyy>
            <iyz>1.97052e-07</iyz>
            <izz>3.62612</izz>
          </inertia>
        </inertial>
        <collision name='base_link_fixed_joint_lump__hend_link_collision'>
          <pose>-0.33246 0 0 0 -0 0</pose>
          <geometry>
            <mesh>
              <scale>1 1 1</scale>
              <uri>model://hendbot/meshes/base_link.STL</uri>
            </mesh>
          </geometry>
          <surface>
            <contact>
              <ode/>
            </contact>
            <friction>
              <ode/>
              <torsional>
                <ode/>
              </torsional>
            </friction>
            <bounce/>
          </surface>
          <max_contacts>10</max_contacts>
        </collision>
        <collision name='base_link_fixed_joint_lump__LBW_Link_collision_1'>
          <pose>-0.28246 0.215 0.035 1.5708 -1.1717 -3.14159</pose>
          <geometry>
            <mesh>
              <scale>1 1 1</scale>
              <uri>model://hendbot/meshes/LBW_Link.STL</uri>
            </mesh>
          </geometry>
          <surface>
            <contact>
              <ode/>
            </contact>
            <friction>
              <ode>
                <mu>0.1</mu>
                <mu2>0.1</mu2>
              </ode>
              <torsional>
                <ode/>
              </torsional>
            </friction>
            <bounce/>
          </surface>
          <max_contacts>10</max_contacts>
        </collision>
        <collision name='base_link_fixed_joint_lump__LFW_Link_collision_2'>
          <pose>0.28245 0.215 0.035103 1.5708 0.76776 3.14159</pose>
          <geometry>
            <mesh>
              <scale>1 1 1</scale>
              <uri>model://hendbot/meshes/LFW_Link.STL</uri>
            </mesh>
          </geometry>
          <surface>
            <contact>
              <ode/>
            </contact>
            <friction>
              <ode>
                <mu>0.1</mu>
                <mu2>0.1</mu2>
              </ode>
              <torsional>
                <ode/>
              </torsional>
            </friction>
            <bounce/>
          </surface>
          <max_contacts>10</max_contacts>
        </collision>
        <collision name='base_link_fixed_joint_lump__RBW_Link_collision_3'>
          <pose>-0.28246 -0.215 0.035 -1.5708 0.11175 -0</pose>
          <geometry>
            <mesh>
              <scale>1 1 1</scale>
              <uri>model://hendbot/meshes/RBW_Link.STL</uri>
            </mesh>
          </geometry>
          <surface>
            <contact>
              <ode/>
            </contact>
            <friction>
              <ode>
                <mu>0.1</mu>
                <mu2>0.1</mu2>
              </ode>
              <torsional>
                <ode/>
              </torsional>
            </friction>
            <bounce/>
          </surface>
          <max_contacts>10</max_contacts>
        </collision>
        <collision name='base_link_fixed_joint_lump__RFW_Link_collision_4'>
          <pose>0.28245 -0.215 0.035103 1.5708 0.34292 3.14159</pose>
          <geometry>
            <mesh>
              <scale>1 1 1</scale>
              <uri>model://hendbot/meshes/RFW_Link.STL</uri>
            </mesh>
          </geometry>
          <surface>
            <contact>
              <ode/>
            </contact>
            <friction>
              <ode>
                <mu>0.1</mu>
                <mu2>0.1</mu2>
              </ode>
              <torsional>
                <ode/>
              </torsional>
            </friction>
            <bounce/>
          </surface>
          <max_contacts>10</max_contacts>
        </collision>
        <collision name='base_link_fixed_joint_lump__laser_frame_collision_5'>
          <pose>-0.01246 0 0.22 0 -0 0</pose>
          <geometry>
            <cylinder>
              <length>0.06</length>
              <radius>0.05</radius>
            </cylinder>
          </geometry>
          <surface>
            <contact>
              <ode/>
            </contact>
            <friction>
              <ode/>
              <torsional>
                <ode/>
              </torsional>
            </friction>
            <bounce/>
          </surface>
          <max_contacts>10</max_contacts>
        </collision>
        <visual name='base_link_fixed_joint_lump__hend_link_visual'>
          <pose>-0.33246 0 0 0 -0 0</pose>
          <geometry>
            <mesh>
              <scale>1 1 1</scale>
              <uri>model://hendbot/meshes/base_link.STL</uri>
            </mesh>
          </geometry>
          <material>
            <script>
              <name>Gazebo/Black</name>
              <uri>file://media/materials/scripts/gazebo.material</uri>
            </script>
          </material>
        </visual>
        <visual name='base_link_fixed_joint_lump__LBW_Link_visual_1'>
          <pose>-0.28246 0.215 0.035 1.5708 -1.1717 -3.14159</pose>
          <geometry>
            <mesh>
              <scale>1 1 1</scale>
              <uri>model://hendbot/meshes/LBW_Link.STL</uri>
            </mesh>
          </geometry>
          <material>
            <script>
              <name>Gazebo/Orange</name>
              <uri>file://media/materials/scripts/gazebo.material</uri>
            </script>
          </material>
        </visual>
        <visual name='base_link_fixed_joint_lump__LFW_Link_visual_2'>
          <pose>0.28245 0.215 0.035103 1.5708 0.76776 3.14159</pose>
          <geometry>
            <mesh>
              <scale>1 1 1</scale>
              <uri>model://hendbot/meshes/LFW_Link.STL</uri>
            </mesh>
          </geometry>
          <material>
            <script>
              <name>Gazebo/Orange</name>
              <uri>file://media/materials/scripts/gazebo.material</uri>
            </script>
          </material>
        </visual>
        <visual name='base_link_fixed_joint_lump__RBW_Link_visual_3'>
          <pose>-0.28246 -0.215 0.035 -1.5708 0.11175 -0</pose>
          <geometry>
            <mesh>
              <scale>1 1 1</scale>
              <uri>model://hendbot/meshes/RBW_Link.STL</uri>
            </mesh>
          </geometry>
          <material>
            <script>
              <name>Gazebo/Orange</name>
              <uri>file://media/materials/scripts/gazebo.material</uri>
            </script>
          </material>
        </visual>
        <visual name='base_link_fixed_joint_lump__RFW_Link_visual_4'>
          <pose>0.28245 -0.215 0.035103 1.5708 0.34292 3.14159</pose>
          <geometry>
            <mesh>
              <scale>1 1 1</scale>
              <uri>model://hendbot/meshes/RFW_Link.STL</uri>
            </mesh>
          </geometry>
          <material>
            <script>
              <name>Gazebo/Orange</name>
              <uri>file://media/materials/scripts/gazebo.material</uri>
            </script>
          </material>
        </visual>
        <visual name='base_link_fixed_joint_lump__laser_frame_visual_5'>
          <pose>-0.01246 0 0.22 0 -0 0</pose>
          <geometry>
            <cylinder>
              <length>0.06</length>
              <radius>0.05</radius>
            </cylinder>
          </geometry>
          <material>
            <script>
              <name>Gazebo/Red</name>
              <uri>file://media/materials/scripts/gazebo.material</uri>
            </script>
          </material>
        </visual>
        <sensor name='laser' type='ray'>
          <visualize>0</visualize>
          <update_rate>10</update_rate>
          <ray>
            <scan>
              <horizontal>
                <samples>360</samples>
                <min_angle>-3.14</min_angle>
                <max_angle>3.14</max_angle>
                <resolution>1</resolution>
              </horizontal>
              <vertical>
                <samples>1</samples>
                <min_angle>0</min_angle>
                <max_angle>0</max_angle>
              </vertical>
            </scan>
            <range>
              <min>0.1</min>
              <max>12</max>
            </range>
          </ray>
          <plugin name='laser_controller' filename='libgazebo_ros_ray_sensor.so'>
            <ros>
              <argument>~/out:=scan</argument>
            </ros>
            <output_type>sensor_msgs/LaserScan</output_type>
            <frame_name>laser_frame</frame_name>
          </plugin>
          <pose>-0.01246 0 0.22 0 -0 0</pose>
        </sensor>
        <self_collide>0</self_collide>
        <enable_wind>0</enable_wind>
        <kinematic>0</kinematic>
      </link>
      <joint name='WLBelt_Joint' type='revolute'>
        <pose relative_to='base_link'>4e-05 0.215 0.035052 1.5708 0.35384 3.14159</pose>
        <parent>base_link</parent>
        <child>WLBelt_Link</child>
        <axis>
          <xyz>0 0 1</xyz>
          <limit>
            <effort>100</effort>
            <velocity>100</velocity>
            <lower>-1e+16</lower>
            <upper>1e+16</upper>
          </limit>
          <dynamics>
            <damping>0.1</damping>
            <friction>0.1</friction>
            <spring_reference>0</spring_reference>
            <spring_stiffness>0</spring_stiffness>
          </dynamics>
        </axis>
      </joint>
      <link name='WLBelt_Link'>
        <pose relative_to='WLBelt_Joint'>0 0 0 0 -0 0</pose>
        <inertial>
          <pose>6e-06 2e-06 0.03 0 -0 0</pose>
          <mass>2.8302</mass>
          <inertia>
            <ixx>0.00487432</ixx>
            <ixy>1.0842e-19</ixy>
            <ixz>-5.95761e-21</ixz>
            <iyy>0.00487432</iyy>
            <iyz>-3.72125e-22</iyz>
            <izz>0.00805052</izz>
          </inertia>
        </inertial>
        <collision name='WLBelt_Link_collision'>
          <pose>0 0 0 0 -0 0</pose>
          <geometry>
            <mesh>
              <scale>1 1 1</scale>
              <uri>model://hendbot/meshes/WLBelt_Link.STL</uri>
            </mesh>
          </geometry>
          <surface>
            <contact>
              <ode/>
            </contact>
            <friction>
              <ode/>
              <torsional>
                <ode/>
              </torsional>
            </friction>
            <bounce/>
          </surface>
          <max_contacts>10</max_contacts>
        </collision>
        <visual name='WLBelt_Link_visual'>
          <pose>0 0 0 0 -0 0</pose>
          <geometry>
            <mesh>
              <scale>1 1 1</scale>
              <uri>model://hendbot/meshes/WLBelt_Link.STL</uri>
            </mesh>
          </geometry>
          <material>
            <script>
              <name>Gazebo/Blue</name>
              <uri>file://media/materials/scripts/gazebo.material</uri>
            </script>
          </material>
        </visual>
        <self_collide>0</self_collide>
        <enable_wind>0</enable_wind>
        <kinematic>0</kinematic>
      </link>
      <joint name='WRBelt_Joint' type='revolute'>
        <pose relative_to='base_link'>4e-05 -0.215 0.035052 -1.5708 0.65732 0</pose>
        <parent>base_link</parent>
        <child>WRBelt_Link</child>
        <axis>
          <xyz>0 0 1</xyz>
          <limit>
            <effort>100</effort>
            <velocity>100</velocity>
            <lower>-1e+16</lower>
            <upper>1e+16</upper>
          </limit>
          <dynamics>
            <damping>0.1</damping>
            <friction>0.1</friction>
            <spring_reference>0</spring_reference>
            <spring_stiffness>0</spring_stiffness>
          </dynamics>
        </axis>
      </joint>
      <link name='WRBelt_Link'>
        <pose relative_to='WRBelt_Joint'>0 0 0 0 -0 0</pose>
        <inertial>
          <pose>-5e-06 4e-06 -0.03 0 -0 0</pose>
          <mass>2.8302</mass>
          <inertia>
            <ixx>0.00487432</ixx>
            <ixy>2.1684e-19</ixy>
            <ixz>9.79617e-36</ixz>
            <iyy>0.00487432</iyy>
            <iyz>7.94184e-36</iyz>
            <izz>0.00805052</izz>
          </inertia>
        </inertial>
        <collision name='WRBelt_Link_collision'>
          <pose>0 0 0 0 -0 0</pose>
          <geometry>
            <mesh>
              <scale>1 1 1</scale>
              <uri>model://hendbot/meshes/WRBelt_Link.STL</uri>
            </mesh>
          </geometry>
          <surface>
            <contact>
              <ode/>
            </contact>
            <friction>
              <ode/>
              <torsional>
                <ode/>
              </torsional>
            </friction>
            <bounce/>
          </surface>
          <max_contacts>10</max_contacts>
        </collision>
        <visual name='WRBelt_Link_visual'>
          <pose>0 0 0 0 -0 0</pose>
          <geometry>
            <mesh>
              <scale>1 1 1</scale>
              <uri>model://hendbot/meshes/WRBelt_Link.STL</uri>
            </mesh>
          </geometry>
          <material>
            <script>
              <name>Gazebo/Blue</name>
              <uri>file://media/materials/scripts/gazebo.material</uri>
            </script>
          </material>
        </visual>
        <self_collide>0</self_collide>
        <enable_wind>0</enable_wind>
        <kinematic>0</kinematic>
      </link>
      <joint name='LFFW_Joint' type='revolute'>
        <pose relative_to='base_link'>0.28245 0.30998 0.035103 1.5708 -1.005 -3.14159</pose>
        <parent>base_link</parent>
        <child>LFFW_Link</child>
        <axis>
          <xyz>0 0 1</xyz>
          <limit>
            <effort>100</effort>
            <velocity>100</velocity>
            <lower>-1e+16</lower>
            <upper>1e+16</upper>
          </limit>
          <dynamics>
            <damping>0.1</damping>
            <friction>0.1</friction>
            <spring_reference>0</spring_reference>
            <spring_stiffness>0</spring_stiffness>
          </dynamics>
        </axis>
      </joint>
      <link name='LFFW_Link'>
        <pose relative_to='LFFW_Joint'>0 0 0 0 -0 0</pose>
        <inertial>
          <pose>-0.016199 0.044173 0.030887 0 -0 0</pose>
          <mass>3.50118</mass>
          <inertia>
            <ixx>0.0402368</ixx>
            <ixy>0.0126939</ixy>
            <ixz>-6.84372e-05</ixz>
            <iyy>0.0103212</iyy>
            <iyz>0.00018326</iyz>
            <izz>0.0481955</izz>
          </inertia>
        </inertial>
        <collision name='LFFW_Link_collision'>
          <pose>0 0 0 0 -0 0</pose>
          <geometry>
            <mesh>
              <scale>1 1 1</scale>
              <uri>model://hendbot/meshes/LFFW_Link.STL</uri>
            </mesh>
          </geometry>
          <surface>
            <contact>
              <ode/>
            </contact>
            <friction>
              <ode>
                <mu>0.1</mu>
                <mu2>0.1</mu2>
              </ode>
              <torsional>
                <ode/>
              </torsional>
            </friction>
            <bounce/>
          </surface>
          <max_contacts>10</max_contacts>
        </collision>
        <collision name='LFFW_Link_fixed_joint_lump__LF_Link_collision_1'>
          <pose>0 0 0 0 -0 1.91705</pose>
          <geometry>
            <mesh>
              <scale>1 1 1</scale>
              <uri>model://hendbot/meshes/LF_Link.STL</uri>
            </mesh>
          </geometry>
          <max_contacts>10</max_contacts>
          <surface>
            <contact>
              <ode/>
            </contact>
            <bounce/>
            <friction>
              <torsional>
                <ode/>
              </torsional>
              <ode/>
            </friction>
          </surface>
        </collision>
        <collision name='LFFW_Link_fixed_joint_lump__LW_Link_collision_2'>
          <pose>-0.103425 0.281385 0 0 0 -2.57584</pose>
          <geometry>
            <mesh>
              <scale>1 1 1</scale>
              <uri>model://hendbot/meshes/LW_Link.STL</uri>
            </mesh>
          </geometry>
          <surface>
            <contact>
              <ode/>
            </contact>
            <friction>
              <ode>
                <mu>0.1</mu>
                <mu2>0.1</mu2>
              </ode>
              <torsional>
                <ode/>
              </torsional>
            </friction>
            <bounce/>
          </surface>
          <max_contacts>10</max_contacts>
        </collision>
        <visual name='LFFW_Link_visual'>
          <pose>0 0 0 0 -0 0</pose>
          <geometry>
            <mesh>
              <scale>1 1 1</scale>
              <uri>model://hendbot/meshes/LFFW_Link.STL</uri>
            </mesh>
          </geometry>
          <material>
            <script>
              <name>Gazebo/Orange</name>
              <uri>file://media/materials/scripts/gazebo.material</uri>
            </script>
          </material>
        </visual>
        <visual name='LFFW_Link_fixed_joint_lump__LF_Link_visual_1'>
          <pose>0 0 0 0 -0 1.91705</pose>
          <geometry>
            <mesh>
              <scale>1 1 1</scale>
              <uri>model://hendbot/meshes/LF_Link.STL</uri>
            </mesh>
          </geometry>
        </visual>
        <visual name='LFFW_Link_fixed_joint_lump__LW_Link_visual_2'>
          <pose>-0.103425 0.281385 0 0 0 -2.57584</pose>
          <geometry>
            <mesh>
              <scale>1 1 1</scale>
              <uri>model://hendbot/meshes/LW_Link.STL</uri>
            </mesh>
          </geometry>
          <material>
            <script>
              <name>Gazebo/Orange</name>
              <uri>file://media/materials/scripts/gazebo.material</uri>
            </script>
          </material>
        </visual>
        <self_collide>0</self_collide>
        <enable_wind>0</enable_wind>
        <kinematic>0</kinematic>
      </link>
      <joint name='RFFW_Joint' type='revolute'>
        <pose relative_to='base_link'>0.28245 -0.31 0.035103 -1.5708 -0.76747 0</pose>
        <parent>base_link</parent>
        <child>RFFW_Link</child>
        <axis>
          <xyz>0 0 1</xyz>
          <limit>
            <effort>100</effort>
            <velocity>100</velocity>
            <lower>-1e+16</lower>
            <upper>1e+16</upper>
          </limit>
          <dynamics>
            <damping>0.1</damping>
            <friction>0.1</friction>
            <spring_reference>0</spring_reference>
            <spring_stiffness>0</spring_stiffness>
          </dynamics>
        </axis>
      </joint>
      <link name='RFFW_Link'>
        <pose relative_to='RFFW_Joint'>0 0 0 0 -0 0</pose>
        <inertial>
          <pose>0.041307 0.022524 -0.030886 0 -0 0</pose>
          <mass>3.50118</mass>
          <inertia>
            <ixx>0.0146412</ixx>
            <ixy>-0.0164836</ixy>
            <ixz>-0.000172565</ixz>
            <iyy>0.0359161</iyy>
            <iyz>-9.27813e-05</iyz>
            <izz>0.0481951</izz>
          </inertia>
        </inertial>
        <collision name='RFFW_Link_collision'>
          <pose>0 0 0 0 -0 0</pose>
          <geometry>
            <mesh>
              <scale>1 1 1</scale>
              <uri>model://hendbot/meshes/RFFW_Link.STL</uri>
            </mesh>
          </geometry>
          <surface>
            <contact>
              <ode/>
            </contact>
            <friction>
              <ode>
                <mu>0.1</mu>
                <mu2>0.1</mu2>
              </ode>
              <torsional>
                <ode/>
              </torsional>
            </friction>
            <bounce/>
          </surface>
          <max_contacts>10</max_contacts>
        </collision>
        <collision name='RFFW_Link_fixed_joint_lump__RF_Link_collision_1'>
          <pose>0 0.01 0 0 -0 0.504452</pose>
          <geometry>
            <mesh>
              <scale>1 1 1</scale>
              <uri>model://hendbot/meshes/RF_Link.STL</uri>
            </mesh>
          </geometry>
          <max_contacts>10</max_contacts>
          <surface>
            <contact>
              <ode/>
            </contact>
            <bounce/>
            <friction>
              <torsional>
                <ode/>
              </torsional>
              <ode/>
            </friction>
          </surface>
        </collision>
        <collision name='RFFW_Link_fixed_joint_lump__RW_Link_collision_2'>
          <pose>0.263308 0.143325 0 0 0 -0.803348</pose>
          <geometry>
            <mesh>
              <scale>1 1 1</scale>
              <uri>model://hendbot/meshes/RW_Link.STL</uri>
            </mesh>
          </geometry>
          <surface>
            <contact>
              <ode/>
            </contact>
            <friction>
              <ode>
                <mu>0.1</mu>
                <mu2>0.1</mu2>
              </ode>
              <torsional>
                <ode/>
              </torsional>
            </friction>
            <bounce/>
          </surface>
          <max_contacts>10</max_contacts>
        </collision>
        <visual name='RFFW_Link_visual'>
          <pose>0 0 0 0 -0 0</pose>
          <geometry>
            <mesh>
              <scale>1 1 1</scale>
              <uri>model://hendbot/meshes/RFFW_Link.STL</uri>
            </mesh>
          </geometry>
          <material>
            <script>
              <name>Gazebo/Orange</name>
              <uri>file://media/materials/scripts/gazebo.material</uri>
            </script>
          </material>
        </visual>
        <visual name='RFFW_Link_fixed_joint_lump__RF_Link_visual_1'>
          <pose>0 0.01 0 0 -0 0.504452</pose>
          <geometry>
            <mesh>
              <scale>1 1 1</scale>
              <uri>model://hendbot/meshes/RF_Link.STL</uri>
            </mesh>
          </geometry>
        </visual>
        <visual name='RFFW_Link_fixed_joint_lump__RW_Link_visual_2'>
          <pose>0.263308 0.143325 0 0 0 -0.803348</pose>
          <geometry>
            <mesh>
              <scale>1 1 1</scale>
              <uri>model://hendbot/meshes/RW_Link.STL</uri>
            </mesh>
          </geometry>
          <material>
            <script>
              <name>Gazebo/Orange</name>
              <uri>file://media/materials/scripts/gazebo.material</uri>
            </script>
          </material>
        </visual>
        <self_collide>0</self_collide>
        <enable_wind>0</enable_wind>
        <kinematic>0</kinematic>
      </link>
      <static>0</static>
      <plugin name='diff_drive' filename='libgazebo_ros_diff_drive.so'>
        <left_joint>WLBelt_Joint</left_joint>
        <right_joint>WRBelt_Joint</right_joint>
        <wheel_separation>0.43</wheel_separation>
        <wheel_diameter>0.17</wheel_diameter>
        <max_wheel_torque>200</max_wheel_torque>
        <max_wheel_acceleration>10.0</max_wheel_acceleration>
        <odometry_frame>odom</odometry_frame>
        <robot_base_frame>base_link</robot_base_frame>
        <publish_odom>1</publish_odom>
        <publish_odom_tf>1</publish_odom_tf>
        <publish_wheel_tf>1</publish_wheel_tf>
      </plugin>
      <pose>0 0 0 0 -0 0</pose>
    </model>
    <model name='unit_box'>
      <pose>1.90958 2.59818 0.5 0 -0 0</pose>
      <link name='link'>
        <inertial>
          <mass>1</mass>
          <inertia>
            <ixx>0.166667</ixx>
            <ixy>0</ixy>
            <ixz>0</ixz>
            <iyy>0.166667</iyy>
            <iyz>0</iyz>
            <izz>0.166667</izz>
          </inertia>
          <pose>0 0 0 0 -0 0</pose>
        </inertial>
        <collision name='collision'>
          <geometry>
            <box>
              <size>1 1 1</size>
            </box>
          </geometry>
          <max_contacts>10</max_contacts>
          <surface>
            <contact>
              <ode/>
            </contact>
            <bounce/>
            <friction>
              <torsional>
                <ode/>
              </torsional>
              <ode/>
            </friction>
          </surface>
        </collision>
        <visual name='visual'>
          <geometry>
            <box>
              <size>1 1 1</size>
            </box>
          </geometry>
          <material>
            <script>
              <name>Gazebo/Grey</name>
              <uri>file://media/materials/scripts/gazebo.material</uri>
            </script>
          </material>
        </visual>
        <self_collide>0</self_collide>
        <enable_wind>0</enable_wind>
        <kinematic>0</kinematic>
      </link>
    </model>
    <state world_name='default'>
      <sim_time>104 14000000</sim_time>
      <real_time>108 455912599</real_time>
      <wall_time>1691363543 154495302</wall_time>
      <iterations>104014</iterations>
      <model name='ground_plane'>
        <pose>0 0 0 0 -0 0</pose>
        <scale>1 1 1</scale>
        <link name='link'>
          <pose>0 0 0 0 -0 0</pose>
          <velocity>0 0 0 0 -0 0</velocity>
          <acceleration>0 0 0 0 -0 0</acceleration>
          <wrench>0 0 0 0 -0 0</wrench>
        </link>
      </model>
      <model name='hendbot'>
        <pose>0.004979 -0.07636 0.039868 -0.000194 7.7e-05 0.085776</pose>
        <scale>1 1 1</scale>
        <link name='LFFW_Link'>
          <pose>0.259837 0.256685 0.074889 1.57153 -1.30163 -3.05652</pose>
          <velocity>-0.0005 -0.000918 0.011384 0.009985 0.028439 -1.5e-05</velocity>
          <acceleration>-0.344602 1.23193 31.9851 -2.37836 0.009515 0.430296</acceleration>
          <wrench>-1.20651 4.3132 111.986 0 -0 0</wrench>
        </link>
        <link name='RFFW_Link'>
          <pose>0.312951 -0.361016 0.07501 -1.57099 -0.414959 0.085851</pose>
          <velocity>-0.000461 -0.001009 0.003558 0.007162 0.013 0.000556</velocity>
          <acceleration>-0.940458 1.20365 -8.73073 -2.8386 -0.536146 -0.612902</acceleration>
          <wrench>-3.29271 4.21421 -30.5679 0 -0 0</wrench>
        </link>
        <link name='WLBelt_Link'>
          <pose>-0.013398 0.137859 0.074879 1.57102 0.353765 -3.05574</pose>
          <velocity>-0.000444 -0.001101 0.009231 0.014893 -0.00581 -0.000137</velocity>
          <acceleration>0.012321 1.28456 28.6972 -1.99689 0.641878 1.85499</acceleration>
          <wrench>0.034872 3.63556 81.2188 0 -0 0</wrench>
        </link>
        <link name='WRBelt_Link'>
          <pose>0.02344 -0.29056 0.074962 -1.57105 0.655118 0.085627</pose>
          <velocity>-0.000499 -0.000923 0.002452 0.013163 -0.007459 5.8e-05</velocity>
          <acceleration>-0.809092 1.47204 -7.01794 0.845815 1.56492 -2.71013</acceleration>
          <wrench>-2.28989 4.16618 -19.8622 0 -0 0</wrench>
        </link>
        <link name='base_link'>
          <pose>0.004979 -0.07636 0.039868 -0.000194 7.7e-05 0.085776</pose>
          <velocity>-0.000291 -0.000516 0.005115 0.012952 -0.007295 0</velocity>
          <acceleration>-1.00589 -1.91439 9.89841 -3.10237 -0.902884 1.43181</acceleration>
          <wrench>-55.2323 -105.117 543.511 0 -0 0</wrench>
        </link>
      </model>
      <model name='unit_box'>
        <pose>1.90958 2.59818 0.5 0 -0 0</pose>
        <scale>1 1 1</scale>
        <link name='link'>
          <pose>1.90958 2.59818 0.5 0 -0 0</pose>
          <velocity>0 0 0 0 -0 0</velocity>
          <acceleration>-0.004709 -9.78112 9.78158 0.712677 -0.009414 -4.3e-05</acceleration>
          <wrench>-0.004709 -9.78112 9.78158 0 -0 0</wrench>
        </link>
      </model>
      <light name='sun'>
        <pose>0 0 10 0 -0 0</pose>
      </light>
    </state>
    <gui fullscreen='0'>
      <camera name='user_camera'>
        <pose>11.2074 -10.1293 6.29851 0 0.275643 2.35619</pose>
        <view_controller>orbit</view_controller>
        <projection_type>perspective</projection_type>
      </camera>
    </gui>
  </world>
</sdf>
